[2024-07-03T15:18:08.672+0000] {local_task_job_runner.py:120} INFO - ::group::Pre task execution logs
[2024-07-03T15:18:08.717+0000] {taskinstance.py:2076} INFO - Dependencies all met for dep_context=non-requeueable deps ti=<TaskInstance: csv_to_postgres2.load_csv_to_postgres manual__2024-07-03T15:18:05.654306+00:00 [queued]>
[2024-07-03T15:18:08.729+0000] {taskinstance.py:2076} INFO - Dependencies all met for dep_context=requeueable deps ti=<TaskInstance: csv_to_postgres2.load_csv_to_postgres manual__2024-07-03T15:18:05.654306+00:00 [queued]>
[2024-07-03T15:18:08.729+0000] {taskinstance.py:2306} INFO - Starting attempt 1 of 1
[2024-07-03T15:18:08.750+0000] {taskinstance.py:2330} INFO - Executing <Task(PythonOperator): load_csv_to_postgres> on 2024-07-03 15:18:05.654306+00:00
[2024-07-03T15:18:08.762+0000] {warnings.py:112} WARNING - /home/***/.local/lib/python3.12/site-packages/***/task/task_runner/standard_task_runner.py:61: DeprecationWarning: This process (pid=153) is multi-threaded, use of fork() may lead to deadlocks in the child.
  pid = os.fork()

[2024-07-03T15:18:08.767+0000] {standard_task_runner.py:63} INFO - Started process 155 to run task
[2024-07-03T15:18:08.766+0000] {standard_task_runner.py:90} INFO - Running: ['***', 'tasks', 'run', 'csv_to_postgres2', 'load_csv_to_postgres', 'manual__2024-07-03T15:18:05.654306+00:00', '--job-id', '54', '--raw', '--subdir', 'DAGS_FOLDER/csv_to_postgres2.py', '--cfg-path', '/tmp/tmpdiacl__5']
[2024-07-03T15:18:08.768+0000] {standard_task_runner.py:91} INFO - Job 54: Subtask load_csv_to_postgres
[2024-07-03T15:18:08.849+0000] {task_command.py:426} INFO - Running <TaskInstance: csv_to_postgres2.load_csv_to_postgres manual__2024-07-03T15:18:05.654306+00:00 [running]> on host ee2e4039efab
[2024-07-03T15:18:09.071+0000] {taskinstance.py:2648} INFO - Exporting env vars: AIRFLOW_CTX_DAG_OWNER='***' AIRFLOW_CTX_DAG_ID='csv_to_postgres2' AIRFLOW_CTX_TASK_ID='load_csv_to_postgres' AIRFLOW_CTX_EXECUTION_DATE='2024-07-03T15:18:05.654306+00:00' AIRFLOW_CTX_TRY_NUMBER='1' AIRFLOW_CTX_DAG_RUN_ID='manual__2024-07-03T15:18:05.654306+00:00'
[2024-07-03T15:18:09.076+0000] {taskinstance.py:430} INFO - ::endgroup::
[2024-07-03T15:18:09.178+0000] {base.py:84} INFO - Using connection ID 'postgres_destino' for task execution.
[2024-07-03T15:18:09.277+0000] {base.py:84} INFO - Using connection ID 'postgres_destino' for task execution.
[2024-07-03T15:18:09.301+0000] {taskinstance.py:441} INFO - ::group::Post task execution logs
[2024-07-03T15:18:09.305+0000] {taskinstance.py:2905} ERROR - Task failed with exception
Traceback (most recent call last):
  File "/home/airflow/.local/lib/python3.12/site-packages/airflow/models/taskinstance.py", line 465, in _execute_task
    result = _execute_callable(context=context, **execute_callable_kwargs)
             ^^^^^^^^^^^^^^^^^^^^^^^^^^^^^^^^^^^^^^^^^^^^^^^^^^^^^^^^^^^^^
  File "/home/airflow/.local/lib/python3.12/site-packages/airflow/models/taskinstance.py", line 432, in _execute_callable
    return execute_callable(context=context, **execute_callable_kwargs)
           ^^^^^^^^^^^^^^^^^^^^^^^^^^^^^^^^^^^^^^^^^^^^^^^^^^^^^^^^^^^^
  File "/home/airflow/.local/lib/python3.12/site-packages/airflow/models/baseoperator.py", line 401, in wrapper
    return func(self, *args, **kwargs)
           ^^^^^^^^^^^^^^^^^^^^^^^^^^^
  File "/home/airflow/.local/lib/python3.12/site-packages/airflow/operators/python.py", line 235, in execute
    return_value = self.execute_callable()
                   ^^^^^^^^^^^^^^^^^^^^^^^
  File "/home/airflow/.local/lib/python3.12/site-packages/airflow/operators/python.py", line 252, in execute_callable
    return self.python_callable(*self.op_args, **self.op_kwargs)
           ^^^^^^^^^^^^^^^^^^^^^^^^^^^^^^^^^^^^^^^^^^^^^^^^^^^^^
  File "/opt/airflow/dags/csv_to_postgres2.py", line 20, in load_csv_to_postgres
    pg_hook.insert_rows(table_name, df.to_dict('records'))
  File "/home/airflow/.local/lib/python3.12/site-packages/airflow/providers/common/sql/hooks/sql.py", line 596, in insert_rows
    cur.executemany(sql, values)
psycopg2.errors.InvalidTextRepresentation: invalid input syntax for type smallint: "category_id"
LINE 1: INSERT INTO categories  VALUES ('category_id','category_name...
                                        ^

[2024-07-03T15:18:09.366+0000] {taskinstance.py:1206} INFO - Marking task as FAILED. dag_id=csv_to_postgres2, task_id=load_csv_to_postgres, run_id=manual__2024-07-03T15:18:05.654306+00:00, execution_date=20240703T151805, start_date=20240703T151808, end_date=20240703T151809
[2024-07-03T15:18:09.506+0000] {standard_task_runner.py:110} ERROR - Failed to execute job 54 for task load_csv_to_postgres (invalid input syntax for type smallint: "category_id"
LINE 1: INSERT INTO categories  VALUES ('category_id','category_name...
                                        ^
; 155)
[2024-07-03T15:18:09.527+0000] {local_task_job_runner.py:240} INFO - Task exited with return code 1
[2024-07-03T15:18:09.575+0000] {taskinstance.py:3503} INFO - 0 downstream tasks scheduled from follow-on schedule check
[2024-07-03T15:18:09.581+0000] {local_task_job_runner.py:222} INFO - ::endgroup::
