[2024-07-03T13:38:31.739+0000] {local_task_job_runner.py:120} INFO - ::group::Pre task execution logs
[2024-07-03T13:38:31.765+0000] {taskinstance.py:2076} INFO - Dependencies all met for dep_context=non-requeueable deps ti=<TaskInstance: postgres_to_csv.run_meltano_task scheduled__2024-07-02T00:00:00+00:00 [queued]>
[2024-07-03T13:38:31.774+0000] {taskinstance.py:2076} INFO - Dependencies all met for dep_context=requeueable deps ti=<TaskInstance: postgres_to_csv.run_meltano_task scheduled__2024-07-02T00:00:00+00:00 [queued]>
[2024-07-03T13:38:31.775+0000] {taskinstance.py:2306} INFO - Starting attempt 1 of 1
[2024-07-03T13:38:31.791+0000] {taskinstance.py:2330} INFO - Executing <Task(BashOperator): run_meltano_task> on 2024-07-02 00:00:00+00:00
[2024-07-03T13:38:31.796+0000] {warnings.py:112} WARNING - /home/***/.local/lib/python3.12/site-packages/***/task/task_runner/standard_task_runner.py:61: DeprecationWarning: This process (pid=59) is multi-threaded, use of fork() may lead to deadlocks in the child.
  pid = os.fork()

[2024-07-03T13:38:31.797+0000] {standard_task_runner.py:63} INFO - Started process 63 to run task
[2024-07-03T13:38:31.800+0000] {standard_task_runner.py:90} INFO - Running: ['***', 'tasks', 'run', 'postgres_to_csv', 'run_meltano_task', 'scheduled__2024-07-02T00:00:00+00:00', '--job-id', '18', '--raw', '--subdir', 'DAGS_FOLDER/postgres_to_csv.py', '--cfg-path', '/tmp/tmp6ozhqyls']
[2024-07-03T13:38:31.804+0000] {standard_task_runner.py:91} INFO - Job 18: Subtask run_meltano_task
[2024-07-03T13:38:31.877+0000] {task_command.py:426} INFO - Running <TaskInstance: postgres_to_csv.run_meltano_task scheduled__2024-07-02T00:00:00+00:00 [running]> on host 39ccb9f93fc5
[2024-07-03T13:38:32.010+0000] {taskinstance.py:2648} INFO - Exporting env vars: AIRFLOW_CTX_DAG_OWNER='***' AIRFLOW_CTX_DAG_ID='postgres_to_csv' AIRFLOW_CTX_TASK_ID='run_meltano_task' AIRFLOW_CTX_EXECUTION_DATE='2024-07-02T00:00:00+00:00' AIRFLOW_CTX_TRY_NUMBER='1' AIRFLOW_CTX_DAG_RUN_ID='scheduled__2024-07-02T00:00:00+00:00'
[2024-07-03T13:38:32.013+0000] {taskinstance.py:430} INFO - ::endgroup::
[2024-07-03T13:38:32.018+0000] {subprocess.py:63} INFO - Tmp dir root location: /tmp
[2024-07-03T13:38:32.020+0000] {subprocess.py:75} INFO - Running command: ['/usr/bin/bash', '-c', 'meltano run tap-postgres target-csv']
[2024-07-03T13:38:32.037+0000] {subprocess.py:86} INFO - Output:
[2024-07-03T13:38:32.046+0000] {subprocess.py:93} INFO - /usr/bin/bash: line 1: meltano: command not found
[2024-07-03T13:38:32.047+0000] {subprocess.py:97} INFO - Command exited with return code 127
[2024-07-03T13:38:32.049+0000] {taskinstance.py:441} INFO - ::group::Post task execution logs
[2024-07-03T13:38:32.087+0000] {taskinstance.py:2905} ERROR - Task failed with exception
Traceback (most recent call last):
  File "/home/airflow/.local/lib/python3.12/site-packages/airflow/models/taskinstance.py", line 465, in _execute_task
    result = _execute_callable(context=context, **execute_callable_kwargs)
             ^^^^^^^^^^^^^^^^^^^^^^^^^^^^^^^^^^^^^^^^^^^^^^^^^^^^^^^^^^^^^
  File "/home/airflow/.local/lib/python3.12/site-packages/airflow/models/taskinstance.py", line 432, in _execute_callable
    return execute_callable(context=context, **execute_callable_kwargs)
           ^^^^^^^^^^^^^^^^^^^^^^^^^^^^^^^^^^^^^^^^^^^^^^^^^^^^^^^^^^^^
  File "/home/airflow/.local/lib/python3.12/site-packages/airflow/models/baseoperator.py", line 401, in wrapper
    return func(self, *args, **kwargs)
           ^^^^^^^^^^^^^^^^^^^^^^^^^^^
  File "/home/airflow/.local/lib/python3.12/site-packages/airflow/operators/bash.py", line 243, in execute
    raise AirflowException(
airflow.exceptions.AirflowException: Bash command failed. The command returned a non-zero exit code 127.
[2024-07-03T13:38:32.103+0000] {taskinstance.py:1206} INFO - Marking task as FAILED. dag_id=postgres_to_csv, task_id=run_meltano_task, run_id=scheduled__2024-07-02T00:00:00+00:00, execution_date=20240702T000000, start_date=20240703T133831, end_date=20240703T133832
[2024-07-03T13:38:32.135+0000] {standard_task_runner.py:110} ERROR - Failed to execute job 18 for task run_meltano_task (Bash command failed. The command returned a non-zero exit code 127.; 63)
[2024-07-03T13:38:32.184+0000] {local_task_job_runner.py:240} INFO - Task exited with return code 1
[2024-07-03T13:38:32.212+0000] {taskinstance.py:3503} INFO - 0 downstream tasks scheduled from follow-on schedule check
[2024-07-03T13:38:32.215+0000] {local_task_job_runner.py:222} INFO - ::endgroup::
